Traceback (most recent call last):
  File "gflownet.py", line 19, in <module>
    import wandb
  File "/home/lchen/miniconda3/envs/FLGFN_set/lib/python3.6/site-packages/wandb/__init__.py", line 27, in <module>
    from wandb import sdk as wandb_sdk
  File "/home/lchen/miniconda3/envs/FLGFN_set/lib/python3.6/site-packages/wandb/sdk/__init__.py", line 4, in <module>
    from .artifacts.artifact import Artifact  # noqa: F401
  File "/home/lchen/miniconda3/envs/FLGFN_set/lib/python3.6/site-packages/wandb/sdk/artifacts/artifact.py", line 36, in <module>
    from wandb.apis.normalize import normalize_exceptions
  File "/home/lchen/miniconda3/envs/FLGFN_set/lib/python3.6/site-packages/wandb/apis/__init__.py", line 44, in <module>
    from .public import Api as PublicApi  # noqa
  File "/home/lchen/miniconda3/envs/FLGFN_set/lib/python3.6/site-packages/wandb/apis/public.py", line 51, in <module>
    from wandb.sdk.launch.errors import LaunchError
  File "/home/lchen/miniconda3/envs/FLGFN_set/lib/python3.6/site-packages/wandb/sdk/launch/__init__.py", line 1, in <module>
    from ._launch import launch
  File "/home/lchen/miniconda3/envs/FLGFN_set/lib/python3.6/site-packages/wandb/sdk/launch/_launch.py", line 12, in <module>
    from .agent import LaunchAgent
  File "/home/lchen/miniconda3/envs/FLGFN_set/lib/python3.6/site-packages/wandb/sdk/launch/agent/__init__.py", line 1, in <module>
    from .agent import LaunchAgent
  File "/home/lchen/miniconda3/envs/FLGFN_set/lib/python3.6/site-packages/wandb/sdk/launch/agent/agent.py", line 15, in <module>
    from wandb.sdk.launch._launch_add import launch_add
  File "/home/lchen/miniconda3/envs/FLGFN_set/lib/python3.6/site-packages/wandb/sdk/launch/_launch_add.py", line 5, in <module>
    import wandb.apis.public as public
AttributeError: module 'wandb' has no attribute 'apis'
